Great observation! If `pd.to_datetime()` works fine with values like `'2024-01'`, the error might stem from **inconsistent or malformed data** in the column you're converting. Here are the possible causes:

---

### **1. Missing Components or Empty Values**
   - If the column contains entries that are completely missing (`NaN`, `None`, or empty strings), `pd.to_datetime()` may raise an error if not handled with `errors='coerce'`.
   - Example:
     ```python
     import pandas as pd
     
     data = {'date': ['2024-01', '', None]}
     df = pd.DataFrame(data)
     pd.to_datetime(df['date'])  # Raises ValueError
     ```

   **Solution:**
   Handle missing values before conversion:
   ```python
   df['date'] = pd.to_datetime(df['date'], errors='coerce')
   ```

---

### **2. Invalid or Malformed Data**
   - Some rows might contain invalid formats or unexpected values (e.g., `'2024-13'`, `'abcd-ef'`, or partial dates without enough components like `'2024'`).
   - Example:
     ```python
     data = {'date': ['2024-01', '2024-13', 'abcd-ef']}
     df = pd.DataFrame(data)
     pd.to_datetime(df['date'])  # Raises ValueError
     ```

   **Solution:**
   Filter out or log invalid rows before conversion:
   ```python
   df['date'] = pd.to_datetime(df['date'], errors='coerce')  # Invalid values become NaT
   print(df[df['date'].isna()])  # Check rows with issues
   ```

---

### **3. Mismatched Types**
   - If the column contains mixed types, like strings and numbers, `pd.to_datetime()` might fail.
   - Example:
     ```python
     data = {'date': ['2024-01', 202401, None]}
     df = pd.DataFrame(data)
     pd.to_datetime(df['date'])  # Raises ValueError
     ```

   **Solution:**
   Ensure all values are strings or can be converted to datetime:
   ```python
   df['date'] = pd.to_datetime(df['date'].astype(str), errors='coerce')
   ```

---

### **4. Partial Dates in Specific Formats**
   - `pd.to_datetime()` handles partial dates like `'2024-01'` (infers day as 1), but inconsistent formats might confuse it. For example:
     ```python
     data = {'date': ['2024-01', '2024']}
     df = pd.DataFrame(data)
     pd.to_datetime(df['date'])  # Works
     ```

     However, if **some rows** are dictionaries or tuples (e.g., JSON-style entries), it might throw the error:
     ```python
     data = {'date': [{'year': 2024, 'month': 1}, '2024-01']}
     df = pd.DataFrame(data)
     pd.to_datetime(df['date'])  # Raises ValueError
     ```

   **Solution:**
   Normalize formats before conversion:
   ```python
   df['date'] = df['date'].apply(lambda x: f"{x['year']}-{x['month']:02d}" if isinstance(x, dict) else x)
   df['date'] = pd.to_datetime(df['date'], errors='coerce')
   ```

---

### **Debugging Approach**
To identify the root cause:
1. Check for invalid rows:
   ```python
   invalid_rows = df[~df['date'].str.match(r'^\d{4}-\d{2}(-\d{2})?$', na=False)]
   print(invalid_rows)
   ```
2. Handle missing, invalid, or inconsistent values before conversion.

Let me know if youâ€™d like further clarification or help debugging! ðŸ˜Š